Workbook

Sheet 测试执行表
A1: 序号 | B1: 用例号 | C1: 分组 | D1: 名称 | E1: 级 | F1: 依据 | G1: 步骤要点 | H1: 判定准则(预期) | I1: 测试结果 | J1: 是否通过 | K1: 测试人 | L1: 日期 | M1: 备注 | N1: 菜单归属
A2: 1 | B2: FA-01 | C2: 火灾报警 | D2: 探测器火警响应（总案）——标准接线；对探测器加烟使其报警；计时起点＝探测器发出报警信号那一刻（确认灯亮/回路信号跳变），不是加烟那一刻 | E2: P0 | F2: 5.4.1.1/5.4.1.2 ↔ 6.3.2 | G2: 探测器自身探测时间归 GB 4715，不计入本判据；建议双通道记录仪（探测器报警特征 vs 控制器声光）自动测间隔 | H2: 见子项 | I2: （未填写原因，需补） | J2: 通过 | L2: 2026-08-18
A3: 2 | B3: FA-01.1 | C3: 火灾报警 | D3: 火警声光响应时限 | E3: P0 | F3: 5.4.1.1/5.4.1.2 | G3: （见父案步骤） | H3: ≤10 s 发出火警声、光信号 | I3: （未填写原因，需补） | J3: 通过 | L3: 2026-08-18
A4: 3 | B4: FA-01.2 | C4: 火灾报警 | D4: 火警总指示灯 | E4: P0 | F4: 5.4.1.1/5.4.1.5 | G4: （见父案步骤） | H4: 火警总指示灯点亮 | I4: （未填写原因，需补） | J4: 通过 | L4: 2026-08-18
A5: 4 | B5: FA-01.3 | C5: 火灾报警 | D5: 部位与时间显示记录 | E5: P0 | F5: 5.4.1.1 | G5: （见父案步骤） | H5: 显示并记录部位与时间（年月日时分秒） | I5: （未填写原因，需补） | J5: 通过 | L5: 2026-08-19 | M5: 部位显示正常；时间缺年份（同源 UI-14.6 时钟停00年），修复后复验
A6: 5 | B6: FA-01.4 | C6: 火灾报警 | D6: 火警保持 | E6: P0 | F6: 5.4.1.1 | G6: （见父案步骤） | H6: 保持至手动复位 | I6: （未填写原因，需补） | J6: 通过 | L6: 2026-08-18
A7: 6 | B7: FA-02 | C7: 火灾报警 | E7: P0 | F7: 5.4.1.1/5.4.1.4 ↔ 6.3.4 | G7: 手报火警响应与类型区分（总案）——使一只手动报警按钮动作，计时。火警基线要求与 FA-01 完全相同（手报也是火灾报警触发器件，5.4.1.1 全套适用） | H7: 见子项 | I7: （未填写原因，需补） | J7: 通过 | L7: 2026-08-18
A8: 7 | B8: FA-02.1 | C8: 火灾报警 | D8: 手报声光响应时限 | E8: P0 | F8: 5.4.1.4 | G8: （见父案步骤） | H8: ≤10 s 发出火警声、光信号 | I8: （未填写原因，需补） | J8: 通过 | L8: 2026-08-18
A9: 8 | B9: FA-02.2 | C9: 火灾报警 | D9: 火警总指示灯 | E9: P0 | F9: 5.4.1.1 | G9: （见父案步骤） | H9: 火警总指示灯点亮 | I9: （未填写原因，需补） | J9: 通过 | L9: 2026-08-18
A10: 9 | B10: FA-02.3 | C10: 火灾报警 | D10: 部位与时间显示记录 | E10: P0 | F10: 5.4.1.1 | G10: （见父案步骤） | H10: 显示并记录部位与时间（年月日时分秒） | I10: 现在只显示了月日，没显示年 | J10: 不通过 | L10: 2026-08-18
A11: 10 | B11: FA-02.4 | C11: 火灾报警 | D11: 火警保持 | E11: P0 | F11: 5.4.1.1 | G11: （见父案步骤） | H11: 保持至手动复位 | I11: （未填写原因，需补） | J11: 通过 | L11: 2026-08-18
A12: 11 | B12: FA-02.6 | C12: 火灾报警 | D12: 手报类型区分 | E12: P0 | F12: 5.4.1.4 | G12: （见父案步骤） | H12: 明确指示为手报报警（区别于探测器） | I12: （未填写原因，需补） | J12: 通过 | L12: 2026-08-18
A13: 12 | B13: FA-03 | C13: 火灾报警 | D13: 手报无延时校验 | E13: P0 | F13: 5.4.1.2/5.4.1.4 ↔ 6.3.11 | G13: 设置报警延时后触发手报 | H13: 手报信号不受报警延时影响，直接 ≤10 s 报警。依据推导（标准无明文"手报禁延时"，由许可式立法省略而来）：5.4.1.2 的延时许可只写给探测器信号；5.4.1.4 给手报的是无条件 10 s、无延时许可——没许可＝禁止；6.3.11 即专查"手报是否被违规配了延时" | I13: 前置依赖报警延时功能，当前无法按用例步骤执行 | J13: 通过 | L13: 2026-08-18
A14: 13 | B14: FA-04 | C14: 火灾报警 | E14: 可选 | F14: 5.4.1.2 ↔ 6.3.10 | G14: 报警延时设置与倒计时（总案）——设置探测器报警延时并修改延时值，触发探测器 | H14: 见子项 | I14: 报警延时功能未设置（未实现） | J14: 不适用 | L14: 2026-08-18
A15: 14 | B15: FA-04.1 | C15: 火灾报警 | D15: 最大延时 | E15: 可选 | F15: 5.4.1.2 | G15: （见父案步骤） | H15: 最大延时 ≤1 min | I15: 同 FA-04 | J15: 不适用 | L15: 2026-08-18
A16: 15 | B16: FA-04.2 | C16: 火灾报警 | D16: 延时光指示 | E16: 可选 | F16: 5.4.1.2 | G16: （见父案步骤） | H16: 延时期间有延时光指示 | I16: 同 FA-04 | J16: 不适用 | L16: 2026-08-18
A17: 16 | B17: FA-04.3 | C17: 火灾报警 | D17: 倒计时显示 | E17: 可选 | F17: 5.4.1.2 | G17: （见父案步骤） | H17: 延时以倒计时显示 | I17: 同 FA-04 | J17: 不适用 | L17: 2026-08-18
A18: 17 | B18: FA-04.4 | C18: 火灾报警 | D18: 设置信息可查 | E18: 可选 | F18: 5.4.1.2 | G18: （见父案步骤） | H18: 设置信息本机可查 | I18: 同 FA-04 | J18: 不适用 | L18: 2026-08-18
A19: 18 | B19: FA-05 | C19: 火灾报警 | D19: 独立供电探测器信息接收 | E19: P1 | F19: 5.4.1.3 ↔ 6.3.3 | G19: 接入线型感温/吸气式感烟/图像型等非控制器直接供电的探测器（条件适用："能够连接……的试样"才测——说明书不声明支持则整条不适用）。接法须为有数据通道的方式（实现本机总线协议挂回路 / 独立 RS485 等接口）；干接点经输入模块不算本条。真实触发手段：吸气式→向采样孔/管路注试验烟；线型感温→对光缆/电缆某段加热；图像型→标准试验火 | H19: 能接收并显示探测器自己产生的部位与报警时间信息（如光纤感温的"第 X 米"、吸气式的"管路 X 孔 X"）。与 FA-01 不重复：FA-01 的部位/时间由控制器查点表+本机时钟生成；本条是透传显示独立智能探测器自带的信息——两条不同的数据通路 | J19: 通过 | L19: 2026-08-19 | M19: 待条件：需线型/吸气式等独立供电探测器；说明书不声明支持则改判不适用；⚠️标通过与待条件（需独立供电探测器）矛盾，请复核是否误点
A20: 19 | B20: FA-06 | C20: 火灾报警 | E20: P0 | F20: 5.4.1.6 ↔ 6.3.5 | G20: 消音与再声响（总案）——火警状态下手动消音；再使另一部位报警 | H20: 见子项 | J20: 通过 | M20: 子项.1/.2 单部位可测；.3/.4 待条件（需第2报警部位）
A21: 20 | B21: FA-06.1 | C21: 火灾报警 | D21: 消音后声停止 | E21: P0 | F21: 5.4.1.6 | G21: （见父案步骤） | H21: 消音后声信号停止 | J21: 通过
A22: 21 | B22: FA-06.2 | C22: 火灾报警 | D22: 消音灯 | E22: P0 | F22: 5.4.1.6 | G22: （见父案步骤） | H22: 消音灯亮 | J22: 通过
A23: 22 | B23: FA-06.3 | C23: 火灾报警 | D23: 新火警再声响 | E23: P0 | F23: 5.4.1.6 | G23: （见父案步骤） | H23: 新火警输入时声信号重新启动 | I23: 同一烟感持续报警，声信号未重新启动 | J23: 通过 | L23: 2026-08-19 | M23: 待条件：需第2报警信号源（必做项，补第2只烟感/手报后测）
A24: 23 | B24: FA-06.4 | C24: 火灾报警 | D24: 新火警消音灯熄灭 | E24: P0 | F24: 5.4.1.6 | G24: （见父案步骤） | H24: 新火警输入时消音灯熄灭 | I24: 新火警输入时消音灯未熄灭 | J24: 不通过 | L24: 2026-08-19 | M24: 待条件：需第2报警信号源（必做项，补第2只烟感/手报后测）
A25: 24 | B25: FA-07 | C25: 火灾报警 | E25: P0 | F25: 5.4.1.7 ↔ 6.3.6/6.3.7 | G25: 首火警保持与多火警循环显示（总案）——逐个增加报警部位直至显示区域不能同时显示。报警源数量说明：6.3.1 的 2+2 基线不够用——6.3.7 原文明写"应增加报警部位数"，所需数量＝本机屏幕同屏火警容量 +1 起步。实操用回路模拟工装按地址批量制造报警，不必堆真探测器 | H25: 见子项 | I25: （未填写原因，需补） | J25: 通过 | L25: 2026-08-18
A26: 25 | B26: FA-07.1 | C26: 火灾报警 | D26: 火警总数显示 | E26: P0 | F26: 5.4.1.7 | G26: （见父案步骤） | H26: 显示火警总数 | I26: （未填写原因，需补） | J26: 通过 | L26: 2026-08-18
A27: 26 | B27: FA-07.2 | C27: 火灾报警 | D27: 首火警持续显示 | E27: P0 | F27: 5.4.1.7 | G27: （见父案步骤） | H27: 首火警持续显示（专用区或共用显示器顶部） | I27: （未填写原因，需补） | J27: 通过 | L27: 2026-08-18
A28: 27 | B28: FA-07.3 | C28: 火灾报警 | D28: 首火警不参与循环 | E28: P0 | F28: 5.4.1.7 | G28: （见父案步骤） | H28: 首火警不参与循环（溢出判定针对后续报警循环区，首火警行不计入） | I28: （未填写原因，需补） | J28: 通过 | L28: 2026-08-18
A29: 28 | B29: FA-07.4 | C29: 火灾报警 | D29: 后续循环显示 | E29: P0 | F29: 5.4.1.7 | G29: （见父案步骤） | H29: 后续按时间顺序循环显示 | I29: （未填写原因，需补） | J29: 通过 | L29: 2026-08-18
A30: 29 | B30: FA-07.5 | C30: 火灾报警 | D30: 手动查询粒度 | E30: P0 | F30: 5.4.1.7 | G30: （见父案步骤） | H30: 手动查询一次只出一条 | I30: （未填写原因，需补） | J30: 通过 | L30: 2026-08-18
A31: 30 | B31: FA-07.6 | C31: 火灾报警 | D31: 事件记录完整 | E31: P0 | F31: ↔ 6.3.7 | G31: （见父案步骤） | H31: 每个火警的事件记录完整（6.3.7 要求核对记录情况） | I31: （未填写原因，需补） | J31: 通过 | L31: 2026-08-18
A32: 31 | B32: FA-08 | C32: 火灾报警 | E32: 可选 | F32: 5.4.1.8 ↔ 6.3.13 | G32: 同一探测器(区)二次确认（总案）——① 发第一个信号（保持 ≥10 s），60 s 内发后续信号——后续信号按产品配置的确认方式给：同一只探测器再报（复位确认法），或同一探测区内另一只探测器报（同区交叉），两种均合法；② 复位后只发第一个信号保持观察 30 min | H32: 见子项 | I32: （未填写原因，需补） | J32: 不适用 | L32: 2026-08-19 | M32: 产品决策2026-08-19：不做二次确认/多信号确认，首信号直接报警——可选条款（准许设有）未实现＝合规，判不适用；若未来实现该功能需恢复测试
A33: 32 | B33: FA-08.1 | C33: 火灾报警 | D33: 第一信号仅提示 | E33: 可选 | F33: 5.4.1.8 a) | G33: （见父案步骤） | H33: 第一信号→仅提示声（火警声或故障声）+ 部位指示，不进入火警状态 | I33: （未填写原因，需补） | J33: 不适用 | L33: 2026-08-19 | M33: 同父案：产品决策不做二次/多信号确认，判不适用
A34: 33 | B34: FA-08.2 | C34: 火灾报警 | D34: 第一信号·总灯不亮 | E34: 可选 | F34: 5.4.1.8 a)/§0.2 | G34: （见父案步骤） | H34: 第一信号时火警总灯不亮 | I34: （未填写原因，需补） | J34: 不适用 | L34: 2026-08-19 | M34: 同父案：产品决策不做二次/多信号确认，判不适用
A35: 34 | B35: FA-08.3 | C35: 火灾报警 | D35: 第一信号·无输出 | E35: 可选 | F35: 5.4.1.8 a)/§0.2 | G35: （见父案步骤） | H35: 第一信号时无任何输出（输出层不解锁） | I35: （未填写原因，需补） | J35: 不适用 | L35: 2026-08-19 | M35: 同父案：产品决策不做二次/多信号确认，判不适用
A36: 35 | B36: FA-08.4 | C36: 火灾报警 | D36: 第一信号·不上报 | E36: 可选 | F36: 5.4.1.8 a)/§0.2 | G36: （见父案步骤） | H36: 第一信号时不上报 CRT | I36: （未填写原因，需补） | J36: 不适用 | L36: 2026-08-19 | M36: 同父案：产品决策不做二次/多信号确认，判不适用
A37: 36 | B37: FA-08.5 | C37: 火灾报警 | D37: 第一信号·不占首火警 | E37: 可选 | F37: 5.4.1.8 a)/§0.2 | G37: （见父案步骤） | H37: 第一信号时不占首火警 | I37: （未填写原因，需补） | J37: 不适用 | L37: 2026-08-19 | M37: 同父案：产品决策不做二次/多信号确认，判不适用
A38: 37 | B38: FA-08.6 | C38: 火灾报警 | D38: 后续信号整包解锁 | E38: 可选 | F38: 5.4.1.8 b) | G38: （见父案步骤） | H38: 60 s 内收到后续信号→火警行为包整体解锁（总灯/声/记录/输出层/上报同时成立） | I38: （未填写原因，需补） | J38: 不适用 | L38: 2026-08-19 | M38: 同父案：产品决策不做二次/多信号确认，判不适用
A39: 38 | B39: FA-08.7 | C39: 火灾报警 | D39: 超时自动复位 | E39: 可选 | F39: 5.4.1.8 c) | G39: （见父案步骤） | H39: 30 min 内无后续信号→对第一信号自动复位（无人工干预、面板恢复监视态） | I39: （未填写原因，需补） | J39: 不适用 | L39: 2026-08-19 | M39: 同父案：产品决策不做二次/多信号确认，判不适用
A40: 39 | B40: FA-09 | C40: 火灾报警 | E40: 可选 | F40: 5.4.1.9 ↔ 6.3.14 | G40: 不同部位两只探测器确认（总案）——① 正面：第一只报警后，按生产者规定的后续报警时间使第二只（不同部位）也报警；② 反面：复位后仅使一只报警，保持规定间隔（≥5 min）观察 | H40: 见子项 | J40: 不适用 | L40: 2026-08-19 | M40: 产品决策2026-08-19：不做二次确认/多信号确认，首信号直接报警——可选条款（准许设有）未实现＝合规，判不适用；若未来实现该功能需恢复测试
...

Sheet 统计
A1: 指标 | B1: 值
A2: 用例总数 | B2: 592
A3: ★ 真正已测(通过+不通过) | B3: =COUNTIF(测试执行表!$J$2:$J$606,"通过")+COUNTIF(测试执行表!$J$2:$J$606,"不通过")
A4: 通过 | B4: =COUNTIF(测试执行表!$J$2:$J$606,"通过")
A5: 不通过 | B5: =COUNTIF(测试执行表!$J$2:$J$606,"不通过")
A6: 不适用 | B6: =COUNTIF(测试执行表!$J$2:$J$606,"不适用")
A7: 待测 | B7: =COUNTIF(测试执行表!$J$2:$J$606,"待测")
A8: 暂不测试 | B8: =COUNTIF(测试执行表!$J$2:$J$606,"暂不测试")
A9: 完全未填 | B9: =COUNTBLANK(测试执行表!$J$2:$J$606)
A10: 通过率(通过/真正已测) | B10: =IF(B3=0,"-",B4/B3)
A11: 覆盖率(真正已测/总数) | B11: =IF(B2=0,"-",B3/B2)

Sheet 菜单覆盖
A1: 大类 | B1: 菜单项 | C1: 对应用例 | D1: 用例数 | E1: 通过 | F1: 不通过 | G1: 待测/暂不 | H1: 未填 | I1: 照片上的权限 | J1: 备注
A2: 查询 | B2: 历史记录 | C2: DP-05、DP-06、DP-07、DP-08、DP-09、DP-10… | D2: 15 | E2: 6 | F2: 5 | G2: 1 | H2: 3 | I2: 操作员
A3: 查询 | B3: 控制器信息 | C3: UI-02 | D3: 1 | E3: 0 | F3: 1 | G3: 0 | H3: 0 | I3: 操作员
A4: 查询 | B4: 级联从机 | C4: UI-05、UI-05.1、UI-05.2 | D4: 3 | E4: 0 | F4: 2 | G4: 0 | H4: 1 | I4: 操作员
A5: 查询 | B5: 设备总览 | C5: UI-03、UI-03.1、UI-03.2、UI-03.3、UI-03.4、UI-03.5… | D5: 7 | E5: 4 | F5: 2 | G5: 0 | H5: 1 | I5: 操作员
A6: 查询 | B6: 单点查询 | C6: UI-04、UI-04.1、UI-04.2、UI-04.3、UI-04.4、UI-04.5 | D6: 6 | E6: 2 | F6: 1 | G6: 0 | H6: 3 | I6: 操作员
A7: 查询 | B7: 检查信息 | C7: CK-01、CK-01.1、CK-01.2、CK-01.3、CK-01.4、CK-02… | D7: 21 | E7: 5 | F7: 0 | G7: 8 | H7: 8 | I7: 操作员
A8: 监控&控制 | B8: 节点设备监控 | C8: UI-07、UI-07.1、UI-07.2、UI-07.3、UI-07.4 | D8: 5 | E8: 0 | F8: 1 | G8: 1 | H8: 3 | I8: 操作
A9: 监控&控制 | B9: 通讯成功率 | C9: UI-08、UI-08.1、UI-08.2、UI-08.3、UI-08.4、UI-08.5 | D9: 6 | E9: 1 | F9: 1 | G9: 1 | H9: 3 | I9: 操作
A10: 监控&控制 | B10: 机内设备监控 | C10: UI-09、UI-09.1、UI-09.2、UI-09.3、UI-09.4、UI-09.5 | D10: 6 | E10: 1 | F10: 0 | G10: 2 | H10: 3 | I10: 操作
A11: 监控&控制 | B11: 启停控制 | C11: UI-10、UI-10.1、UI-10.2、UI-10.3、UI-10.4、UI-10.5 | D11: 6 | E11: 2 | F11: 1 | G11: 1 | H11: 2 | I11: 操作
A12: 监控&控制 | B12: 屏蔽控制 | C12: SH-01、SH-01.1、SH-01.2、SH-01.3、SH-01.4、SH-02… | D12: 26 | E12: 2 | F12: 4 | G12: 1 | H12: 19 | I12: 操作
A13: 设置 | B13: 用户登陆 | C13: UI-12、UI-12.1、UI-12.2、UI-12.3 | D13: 4 | E13: 4 | F13: 0 | G13: 0 | H13: 0 | I13: 操作
A14: 设置 | B14: 基础设置 | C14: UI-14、UI-14.1、UI-14.2、UI-14.3、UI-14.4、UI-14.5… | D14: 9 | E14: 1 | F14: 3 | G14: 1 | H14: 4 | I14: 操作
A15: 设置 | B15: 密码设置 | C15: UI-13、UI-13.1、UI-13.2、UI-13.3、UI-13.4、UI-13.5 | D15: 6 | E15: 3 | F15: 1 | G15: 0 | H15: 2 | I15: 操作 | J15: ⚠️ 改 Ⅲ 级密码按 OP-02.2 应拒绝 Ⅱ 级；菜单标「操作」级需核
A16: 设置 | B16: 联网设置 | C16: UI-15、UI-15.1、UI-15.2 | D16: 3 | E16: 0 | F16: 0 | G16: 3 | H16: 0 | I16: 操作 | J16: ⚠️ 参数修改属「输入/更改数据」，OP-02.2 要求 Ⅱ 级拒绝
A17: 设置 | B17: 节点设置 | C17: UI-16、UI-16.1、UI-16.2 | D17: 3 | E17: 0 | F17: 1 | G17: 0 | H17: 2 | I17: 操作 | J17: ⚠️ 点表编辑属「数据修改」，OP-03.1 要求 Ⅲ 级；菜单标「操作」级需核
A18: 设置 | B18: 操作模式设置 | C18: UI-17、UI-17.1、UI-17.2、UI-17.3 | D18: 4 | E18: 1 | F18: 2 | G18: 1 | H18: 0 | I18: 操作
A19: 调试 | B19: 点位注册 | C19: UI-18、UI-18.1、UI-18.2、UI-18.3、UI-18.4、UI-18.5 | D19: 6 | E19: 2 | F19: 2 | G19: 1 | H19: 1 | I19: 调试员
A20: 调试 | B20: 配置导入 | C20: UI-19、UI-19.1、UI-19.2、UI-19.3 | D20: 4 | E20: 0 | F20: 1 | G20: 0 | H20: 3 | I20: 调试员
A21: 调试 | B21: 联动编程 | C21: UI-20、UI-20.1、UI-20.2 | D21: 3 | E21: 0 | F21: 1 | G21: 0 | H21: 2 | I21: 调试员
A22: 调试 | B22: 调试助手 | C22: UI-21、UI-21.1、UI-21.2、UI-21.3、UI-21.4 | D22: 5 | E22: 0 | F22: 0 | G22: 0 | H22: 5 | I22: 调试员
A23: 调试 | B23: 联网注册 | C23: UI-22 | D23: 1 | E23: 0 | F23: 0 | G23: 1 | H23: 0 | I23: 调试员
A24: 调试 | B24: 直控调试 | D24: 0 | E24: 0 | F24: 0 | G24: 0 | H24: 0 | I24: 调试员 | J24: ⚠️ 与「调试助手」共用 UI-21，菜单上是两个独立入口，建议拆为 UI-21.1/.2
A25: 维护 | B25: 固件升级 | C25: UI-23、UI-23.1、UI-23.2、UI-23.3 | D25: 4 | E25: 0 | F25: 0 | G25: 0 | H25: 4 | I25: 生产商
A26: 维护 | B26: 记录导出 | C26: UI-24、UI-24.1、UI-24.2、UI-24.3 | D26: 4 | E26: 0 | F26: 0 | G26: 0 | H26: 4 | I26: 生产商
A27: 维护 | B27: 恢复出厂设置 | C27: UI-25、UI-25.1、UI-25.2、UI-25.3、UI-25.4 | D27: 5 | E27: 0 | F27: 0 | G27: 0 | H27: 5 | I27: 生产商

Sheet 缺陷汇总
A1: 用例号 | B1: 菜单归属 | C1: 名称 | D1: 级 | E1: 实测结果 | F1: 疑似同源缺陷
A2: FA-04 | D2: 可选 | E2: 报警延时功能未设置（未实现）
A3: FA-04.1 | C3: 最大延时 | D3: 可选 | E3: 同 FA-04
A4: FA-04.2 | C4: 延时光指示 | D4: 可选 | E4: 同 FA-04
A5: FA-04.3 | C5: 倒计时显示 | D5: 可选 | E5: 同 FA-04
A6: FA-04.4 | C6: 设置信息可查 | D6: 可选 | E6: 同 FA-04
A7: FA-11 | D7: P1 | E7: 信息显示时间缺年份("01月02日 00:20:58"),不满足年月日时分秒
A8: ST-05 | C8: 开机自检·故障优先显示 | D8: P1 | E8: 现在卡到启动页面了
A9: DP-05 | B9: 查询 / 历史记录 | C9: 历史记录·全部查询按钮 | D9: P1 | E9: 全部查询按钮点击无响应 | F9: ★ 全局导航缺陷
A10: UI-01.3 | B10: 查询 / 历史记录 | C10: 菜单页信息项完整 | D10: P1 | E10: 缺少其他
A11: UI-02 | B11: 查询 / 控制器信息 | C11: 控制器信息 | D11: P1 | E11: 没有容量
A12: UI-04.3 | B12: 查询 / 单点查询 | C12: 单点查询·返回按钮 | D12: P1 | E12: 显示的菜单按钮，点击到了菜单页 | F12: ★ 全局导航缺陷
A13: UI-05.1 | B13: 查询 / 级联从机 | C13: 级联从机·无从机显示 | D13: P1 | E13: 无从机的情况下，有显示对勾的
A14: UI-07.4 | B14: 监控&控制 / 节点设备监控 | C14: 节点监控·返回按钮 | D14: P1 | E14: 显示的是菜单按钮，点击跳到菜单页（与 UI-26/27、UI-03.4/.6、UI-04.3、UI-05.2、UI-18.3、UI-01.4 同源） | F14: ★ 全局导航缺陷
A15: UI-08.4 | B15: 监控&控制 / 通讯成功率 | C15: 通讯成功率·返回按钮 | D15: P1 | E15: 显示的是菜单按钮，点击跳到菜单页（全局导航缺陷，同源第 11 处） | F15: ★ 全局导航缺陷
A16: UI-10.4 | B16: 监控&控制 / 启停控制 | C16: 启停·返回按钮响应 | D16: P1 | E16: ⚠️与其他页不同：本页返回按钮显示正确，但点击无响应。属全局导航缺陷的第二亚型（显示对/不响应），另一亚型为显示成菜单按钮 | F16: ★ 全局导航缺陷
A17: UI-11.1 | B17: 监控&控制 / 屏蔽控制 | C17: 屏蔽·空地址输入校验 | D17: P1 | E17: ❌ 空输入可点击且生效：物理屏蔽灯点亮并发声。控制器进入"虚假屏蔽态"（无任何设备被屏蔽却亮屏蔽灯），与 SH-01.4「屏蔽总灯亮并显示屏蔽时间」语义冲突；须复核 CK-08 屏蔽数量列此时显示值
A18: UI-11.4 | B18: 监控&控制 / 屏蔽控制 | C18: 解除屏蔽·声信号未随状态停止 | D18: P1 | E18: ❌ 解除屏蔽后物理屏蔽灯已关闭，但声音未停；必须手动按消音键声音才消失 → 声信号与状态解耦
A19: UI-11.5 | B19: 监控&控制 / 屏蔽控制 | C19: 消音灯常亮·不自动复位 | D19: P0 | E19: ❌ 物理消音灯一直亮着不复位。⚠️安全风险：若消音态未退出，下一次真火警时(a)值班员会误判"已消过音"(b)火警声可能被压制。须立即验证：当前消音灯亮态下触发新火警(加烟/按手报)，看消音灯是否熄灭、火警声是否响起(FA-06.4 / LC-11.4)。注：FT-04.1「新故障声再启动」已测通过，但火警侧未验
A20: UI-11.6 | B20: 监控&控制 / 屏蔽控制 | C20: 屏蔽页·返回按钮响应 | D20: P1 | E20: ❌ 返回按钮无响应（全局导航缺陷·亚型B：显示对/不响应） | F20: ★ 全局导航缺陷
A21: UI-13.4 | B21: 设置 / 密码设置 | C21: 密码设置·返回按钮 | D21: P1 | E21: ❌ 返回按钮不正确（全局导航缺陷） | F21: ★ 全局导航缺陷
A22: UI-14.5 | B22: 设置 / 基础设置 | C22: 基础设置·返回按钮 | D22: P1 | E22: ❌ 返回按钮不正确（全局导航缺陷） | F22: ★ 全局导航缺陷
A23: UI-14.6 | B23: 设置 / 基础设置 | C23: ⚠️系统时钟停在00年 | D23: P0 | E23: ❌ 当前值 = 00年01月02日 05:36:11 → 年份为00，系上电累计计时而非真实时间。⚠️根因关联：已判不通过的 FA-11「信息显示时间缺年份」与 UI-28 很可能不是显示层丢字段，而是时钟本身无效。影响面：全部黑匣子事件时间戳、SH-01.4屏蔽时间、CM-03授时。建议动作：在本页设为真实时间→确定→复查 UI-14.1(生效)/UI-14.3(日误差≤6s)/FA-11/UI-28，一次可收4条
A24: UI-14.7 | B24: 设置 / 基础设置 | C24: ⚠️声音使能可关闭强制声信号 | D24: P0 | E24: ❌ 界面提供分项开关且当前状态为：报警✓开 / 监管☐关 / 启动☐关 / 反馈☐关。⚠️「监管」声被关闭直接抵触 SV-01.1。待判别：该开关若控制的是标准强制的报警声→设计违标；若仅控制按键提示音→改判不适用。判别方法：保持当前状态触发一次监管报警，无声则违标成立。注意 SV 组8条用例全部以"监管声能响"为前提，此项不定论则 SV 组无法测
A25: UI-16 | B25: 设置 / 节点设置 | D25: P1 | E25: 节点设置：菜单入口存在，点击无响应（功能未开发） | F25: ★ 全局导航缺陷
A26: UI-17.1 | B26: 设置 / 操作模式设置 | C26: 操作模式·返回按钮 | D26: P1 | E26: ❌ 显示的是菜单按钮，点击跳到菜单页（全局导航缺陷·亚型A） | F26: ★ 全局导航缺陷
A27: UI-17.3 | B27: 设置 / 操作模式设置 | C27: ⚠️免打扰模式·状态可区分与值班提示 | D27: P0 | E27: ❌ 测试人现场提出：该模式为开发人员使用，但缺少对值班人员的明显提示，存在影响正常功能而不自知的风险。对照 OP-05.3，此非"建议"而是标准要求：需验证 ①主界面是否有常驻区别标识（非仅本设置页内）②顶栏状态是否变化 ③上传/打印信息是否带区别标识 ④是否有超时自动退回正常运行
A28: UI-18.3 | B28: 调试 / 点位注册 | C28: 设备注册·返回按钮 | D28: P1 | E28: 左上角返回按钮点击无响应 | F28: ★ 全局导航缺陷
A29: UI-19 | B29: 调试 / 配置导入 | D29: P1 | E29: 功能未实现（菜单入口存在，功能未开发）
A30: UI-20 | B30: 调试 / 联动编程 | D30: P1 | E30: 功能未实现（菜单入口存在，功能未开发）
A31: UI-26 | C31: 检查页右上角返回按钮 | D31: P1 | E31: 右上角为菜单按钮,点击进入信息显示页,非返回主页 | F31: ★ 全局导航缺陷
A32: UI-27 | C32: 信息显示页右上角返回按钮 | D32: P1 | E32: 右上角同样非返回
A33: UI-28 | C33: 信息显示时间格式 | D33: P1 | E33: 时间显示"01月02日 00:20:58"缺年份
A34: UI-01.4 | B34: 查询 / 历史记录 | C34: 菜单页·详情返回 | D34: P1 | E34: 无法返回到菜单页 | F34: ★ 全局导航缺陷
A35: DP-11 | B35: 查询 / 历史记录 | C35: 历史记录·详情返回按钮 | D35: P1 | E35: 应该显示返回按钮，显示了菜单按钮。点击按钮无响应 | F35: ★ 全局导航缺陷
A36: DP-13 | B36: 查询 / 历史记录 | C36: 历史记录·按回路查询 | D36: P1 | E36: 回路1有故障，查询回路1地址1，应该有数据，查询列表也无数据，查询回路1，地址2，却有数据
A37: UI-18.5 | B37: 调试 / 点位注册 | C37: 点位注册·右上角返回按钮 | D37: P1 | E37: ❌ 显示的是菜单按钮，点击跳到菜单列表页（全局导航缺陷·亚型A：显示错）。注：本页左上角返回按钮另有"点击无响应"问题(UI-18.3，亚型B)，两个按钮各自有问题 | F37: ★ 全局导航缺陷
A38: UI-03.4 | B38: 查询 / 设备总览 | C38: 设备总览·列表返回按钮 | D38: P1 | E38: 点击无响应 | F38: ★ 全局导航缺陷
A39: UI-03.6 | B39: 查询 / 设备总览 | C39: 设备总览·详情返回按钮 | D39: P1 | E39: 显示的菜单按钮，点击无响应 | F39: ★ 全局导航缺陷
A40: UI-05.2 | B40: 查询 / 级联从机 | C40: 级联从机·返回按钮 | D40: P1 | E40: 显示的菜单按钮，点击到了菜单页 | F40: ★ 全局导航缺陷
...

Sheet 分组统计
A1: 分组 | B1: 用例数 | C1: 通过 | D1: 不通过 | E1: 不适用 | F1: 待测/暂不 | G1: 未填
A2: 火灾报警 | B2: =COUNTIF(测试执行表!C2:C593,A2) | C2: =COUNTIFS(测试执行表!C2:C593,A2,测试执行表!J2:J593,"通过") | D2: =COUNTIFS(测试执行表!C2:C593,A2,测试执行表!J2:J593,"不通过") | E2: =COUNTIFS(测试执行表!C2:C593,A2,测试执行表!J2:J593,"不适用") | F2: =COUNTIFS(测试执行表!C2:C593,A2,测试执行表!J2:J593,"待测")+COUNTIFS(测试执行表!C2:C593,A2,测试执行表!J2:J593,"暂不测试") | G2: =B2-C2-D2-E2-F2
A3: 报警控制(联动输出) | B3: =COUNTIF(测试执行表!C2:C593,A3) | C3: =COUNTIFS(测试执行表!C2:C593,A3,测试执行表!J2:J593,"通过") | D3: =COUNTIFS(测试执行表!C2:C593,A3,测试执行表!J2:J593,"不通过") | E3: =COUNTIFS(测试执行表!C2:C593,A3,测试执行表!J2:J593,"不适用") | F3: =COUNTIFS(测试执行表!C2:C593,A3,测试执行表!J2:J593,"待测")+COUNTIFS(测试执行表!C2:C593,A3,测试执行表!J2:J593,"暂不测试") | G3: =B3-C3-D3-E3-F3
A4: 故障报警 | B4: =COUNTIF(测试执行表!C2:C593,A4) | C4: =COUNTIFS(测试执行表!C2:C593,A4,测试执行表!J2:J593,"通过") | D4: =COUNTIFS(测试执行表!C2:C593,A4,测试执行表!J2:J593,"不通过") | E4: =COUNTIFS(测试执行表!C2:C593,A4,测试执行表!J2:J593,"不适用") | F4: =COUNTIFS(测试执行表!C2:C593,A4,测试执行表!J2:J593,"待测")+COUNTIFS(测试执行表!C2:C593,A4,测试执行表!J2:J593,"暂不测试") | G4: =B4-C4-D4-E4-F4
A5: 屏蔽 | B5: =COUNTIF(测试执行表!C2:C593,A5) | C5: =COUNTIFS(测试执行表!C2:C593,A5,测试执行表!J2:J593,"通过") | D5: =COUNTIFS(测试执行表!C2:C593,A5,测试执行表!J2:J593,"不通过") | E5: =COUNTIFS(测试执行表!C2:C593,A5,测试执行表!J2:J593,"不适用") | F5: =COUNTIFS(测试执行表!C2:C593,A5,测试执行表!J2:J593,"待测")+COUNTIFS(测试执行表!C2:C593,A5,测试执行表!J2:J593,"暂不测试") | G5: =B5-C5-D5-E5-F5
A6: 监管报警 | B6: =COUNTIF(测试执行表!C2:C593,A6) | C6: =COUNTIFS(测试执行表!C2:C593,A6,测试执行表!J2:J593,"通过") | D6: =COUNTIFS(测试执行表!C2:C593,A6,测试执行表!J2:J593,"不通过") | E6: =COUNTIFS(测试执行表!C2:C593,A6,测试执行表!J2:J593,"不适用") | F6: =COUNTIFS(测试执行表!C2:C593,A6,测试执行表!J2:J593,"待测")+COUNTIFS(测试执行表!C2:C593,A6,测试执行表!J2:J593,"暂不测试") | G6: =B6-C6-D6-E6-F6
A7: 自检 | B7: =COUNTIF(测试执行表!C2:C593,A7) | C7: =COUNTIFS(测试执行表!C2:C593,A7,测试执行表!J2:J593,"通过") | D7: =COUNTIFS(测试执行表!C2:C593,A7,测试执行表!J2:J593,"不通过") | E7: =COUNTIFS(测试执行表!C2:C593,A7,测试执行表!J2:J593,"不适用") | F7: =COUNTIFS(测试执行表!C2:C593,A7,测试执行表!J2:J593,"待测")+COUNTIFS(测试执行表!C2:C593,A7,测试执行表!J2:J593,"暂不测试") | G7: =B7-C7-D7-E7-F7
A8: 显示与查询 | B8: =COUNTIF(测试执行表!C2:C593,A8) | C8: =COUNTIFS(测试执行表!C2:C593,A8,测试执行表!J2:J593,"通过") | D8: =COUNTIFS(测试执行表!C2:C593,A8,测试执行表!J2:J593,"不通过") | E8: =COUNTIFS(测试执行表!C2:C593,A8,测试执行表!J2:J593,"不适用") | F8: =COUNTIFS(测试执行表!C2:C593,A8,测试执行表!J2:J593,"待测")+COUNTIFS(测试执行表!C2:C593,A8,测试执行表!J2:J593,"暂不测试") | G8: =B8-C8-D8-E8-F8
A9: 检查功能 | B9: =COUNTIF(测试执行表!C2:C593,A9) | C9: =COUNTIFS(测试执行表!C2:C593,A9,测试执行表!J2:J593,"通过") | D9: =COUNTIFS(测试执行表!C2:C593,A9,测试执行表!J2:J593,"不通过") | E9: =COUNTIFS(测试执行表!C2:C593,A9,测试执行表!J2:J593,"不适用") | F9: =COUNTIFS(测试执行表!C2:C593,A9,测试执行表!J2:J593,"待测")+COUNTIFS(测试执行表!C2:C593,A9,测试执行表!J2:J593,"暂不测试") | G9: =B9-C9-D9-E9-F9
A10: 电源 | B10: =COUNTIF(测试执行表!C2:C593,A10) | C10: =COUNTIFS(测试执行表!C2:C593,A10,测试执行表!J2:J593,"通过") | D10: =COUNTIFS(测试执行表!C2:C593,A10,测试执行表!J2:J593,"不通过") | E10: =COUNTIFS(测试执行表!C2:C593,A10,测试执行表!J2:J593,"不适用") | F10: =COUNTIFS(测试执行表!C2:C593,A10,测试执行表!J2:J593,"待测")+COUNTIFS(测试执行表!C2:C593,A10,测试执行表!J2:J593,"暂不测试") | G10: =B10-C10-D10-E10-F10
A11: 看门狗 | B11: =COUNTIF(测试执行表!C2:C593,A11) | C11: =COUNTIFS(测试执行表!C2:C593,A11,测试执行表!J2:J593,"通过") | D11: =COUNTIFS(测试执行表!C2:C593,A11,测试执行表!J2:J593,"不通过") | E11: =COUNTIFS(测试执行表!C2:C593,A11,测试执行表!J2:J593,"不适用") | F11: =COUNTIFS(测试执行表!C2:C593,A11,测试执行表!J2:J593,"待测")+COUNTIFS(测试执行表!C2:C593,A11,测试执行表!J2:J593,"暂不测试") | G11: =B11-C11-D11-E11-F11
A12: 通信 | B12: =COUNTIF(测试执行表!C2:C593,A12) | C12: =COUNTIFS(测试执行表!C2:C593,A12,测试执行表!J2:J593,"通过") | D12: =COUNTIFS(测试执行表!C2:C593,A12,测试执行表!J2:J593,"不通过") | E12: =COUNTIFS(测试执行表!C2:C593,A12,测试执行表!J2:J593,"不适用") | F12: =COUNTIFS(测试执行表!C2:C593,A12,测试执行表!J2:J593,"待测")+COUNTIFS(测试执行表!C2:C593,A12,测试执行表!J2:J593,"暂不测试") | G12: =B12-C12-D12-E12-F12
A13: 存储单元(黑匣子) | B13: =COUNTIF(测试执行表!C2:C593,A13) | C13: =COUNTIFS(测试执行表!C2:C593,A13,测试执行表!J2:J593,"通过") | D13: =COUNTIFS(测试执行表!C2:C593,A13,测试执行表!J2:J593,"不通过") | E13: =COUNTIFS(测试执行表!C2:C593,A13,测试执行表!J2:J593,"不适用") | F13: =COUNTIFS(测试执行表!C2:C593,A13,测试执行表!J2:J593,"待测")+COUNTIFS(测试执行表!C2:C593,A13,测试执行表!J2:J593,"暂不测试") | G13: =B13-C13-D13-E13-F13
A14: 操作级别 | B14: =COUNTIF(测试执行表!C2:C593,A14) | C14: =COUNTIFS(测试执行表!C2:C593,A14,测试执行表!J2:J593,"通过") | D14: =COUNTIFS(测试执行表!C2:C593,A14,测试执行表!J2:J593,"不通过") | E14: =COUNTIFS(测试执行表!C2:C593,A14,测试执行表!J2:J593,"不适用") | F14: =COUNTIFS(测试执行表!C2:C593,A14,测试执行表!J2:J593,"待测")+COUNTIFS(测试执行表!C2:C593,A14,测试执行表!J2:J593,"暂不测试") | G14: =B14-C14-D14-E14-F14
A15: 气体灭火控制器 | B15: =COUNTIF(测试执行表!C2:C593,A15) | C15: =COUNTIFS(测试执行表!C2:C593,A15,测试执行表!J2:J593,"通过") | D15: =COUNTIFS(测试执行表!C2:C593,A15,测试执行表!J2:J593,"不通过") | E15: =COUNTIFS(测试执行表!C2:C593,A15,测试执行表!J2:J593,"不适用") | F15: =COUNTIFS(测试执行表!C2:C593,A15,测试执行表!J2:J593,"待测")+COUNTIFS(测试执行表!C2:C593,A15,测试执行表!J2:J593,"暂不测试") | G15: =B15-C15-D15-E15-F15
A16: 结构与外观 | B16: =COUNTIF(测试执行表!C2:C593,A16) | C16: =COUNTIFS(测试执行表!C2:C593,A16,测试执行表!J2:J593,"通过") | D16: =COUNTIFS(测试执行表!C2:C593,A16,测试执行表!J2:J593,"不通过") | E16: =COUNTIFS(测试执行表!C2:C593,A16,测试执行表!J2:J593,"不适用") | F16: =COUNTIFS(测试执行表!C2:C593,A16,测试执行表!J2:J593,"待测")+COUNTIFS(测试执行表!C2:C593,A16,测试执行表!J2:J593,"暂不测试") | G16: =B16-C16-D16-E16-F16
A17: 人机菜单(产品级) | B17: =COUNTIF(测试执行表!C2:C593,A17) | C17: =COUNTIFS(测试执行表!C2:C593,A17,测试执行表!J2:J593,"通过") | D17: =COUNTIFS(测试执行表!C2:C593,A17,测试执行表!J2:J593,"不通过") | E17: =COUNTIFS(测试执行表!C2:C593,A17,测试执行表!J2:J593,"不适用") | F17: =COUNTIFS(测试执行表!C2:C593,A17,测试执行表!J2:J593,"待测")+COUNTIFS(测试执行表!C2:C593,A17,测试执行表!J2:J593,"暂不测试") | G17: =B17-C17-D17-E17-F17
A18: 型式试验 | B18: =COUNTIF(测试执行表!C2:C593,A18) | C18: =COUNTIFS(测试执行表!C2:C593,A18,测试执行表!J2:J593,"通过") | D18: =COUNTIFS(测试执行表!C2:C593,A18,测试执行表!J2:J593,"不通过") | E18: =COUNTIFS(测试执行表!C2:C593,A18,测试执行表!J2:J593,"不适用") | F18: =COUNTIFS(测试执行表!C2:C593,A18,测试执行表!J2:J593,"待测")+COUNTIFS(测试执行表!C2:C593,A18,测试执行表!J2:J593,"暂不测试") | G18: =B18-C18-D18-E18-F18
A19: 合计 | B19: =SUM(B2:B18) | C19: =SUM(C2:C593) | D19: =SUM(D2:D18) | E19: =SUM(E2:E18) | F19: =SUM(F2:F18) | G19: =SUM(G2:G18)
